Workbook

Sheet CALIBRACIÓN PSV
E1: CERTIFICADO DE CALIBRACIÓN DE VÁLVULA DE SEGURIDAD EN BANCO DE PRUEBAS
E3: CÓDIGO | G3: OYS-FO-43 | I3: VERSIÓN | K3: 09 | L3: FECHA | N3: 46007
B4: SECCIÓN 1. INFORMACIÓN DEL LABORATORIO
C6: MÉTODO UTILIZADO: | E6: ASME PTC 25 - MÉTODO DIRECTO | I6: FECHA DE RECEPCIÓN:
C8: LUGAR DE PRUEBA: | I8: FECHA DE CALIBRACIÓN: | R8: LABORATORIO VALSER
R9: INSTALACIONES DEL CLIENTE
C10: NÚMERO DE CERTIFICADO: | E10: CAL- | I10: FECHA DE EMISIÓN:
B12: SECCIÓN 2. INFORMACIÓN DEL CLIENTE
C14: CLIENTE: | G14: CONTACTO: | K14: CORREO:
B16: SECCIÓN 3. INFORMACIÓN VÁLVULA DE SEGURIDAD
C18: LOCALIZACIÓN: | J18: TAG: | L18: Nº PRECINTO:
C20: MARCA: | F20: TAMAÑO: | J20: CONEXIÓN ENTxSAL:
C22: MODELO: | F22: Nº SERIE: | J22: PRESIÓN CALIBRACIÓN: | N22: psi
B24: SECCIÓN 4. PATRONES DE TRABAJO
C26: EQUIPO | D26: MARCA | E26: MODELO | G26: SERIAL | H26: CALIBRADO POR | K26: RANGO | L26: FECHA CALIBRACIÓN | N26: N° DE CERTIFICADO | R26: MARCA | S26: MODELO | T26: SERIAL | U26: FECHA DE CALIBRACIÓN | V26: RANGO | W26: CERTIFICADO | X26: CERTIFICADOR | Z26: MARCA | AA26: MODELO | AB26: SERIAL | AC26: FECHA DE CALIBRACIÓN | AD26: RANGO | AE26: CERTIFICADO | AF26: CERTIFICADOR
C27: MANÓMETRO | D27: =IF(G27=T27,R27,IF(G27=T28,R28,IF(G27=T29,R29,R30))) -> WIKA | E27: =IF(G27=T27,S27,IF(G27=T28,S28,IF(G27=T29,S29,S30))) -> CPG1500 | G27: =IF('DATOS INCERTIDUMBRE'!$G$3="Manómetro Crystal 5k",T28,IF('DATOS INCERTIDUMBRE'!$G$3="Manómetro Crystal 1K",T29,IF('DATOS INCERTIDUMBRE'!$G$3="Manómetro Additel",T27,T30))) -> 1A047Q87N2E | H27: =IF(G27=T27,X27,IF(G27=T28,X28,IF(G27=T29,X29,X30))) -> FLEXILATINA | K27: =IF(G27=T27,V27,IF(G27=T28,V28,IF(G27=T29,V29,V30))) -> (0 a 1000) psi | L27: =IF(G27=T27,U27,IF(G27=T28,U28,IF(G27=T29,U29,U30))) -> 46020 | N27: =IF(G27=T27,W27,IF(G27=T28,W28,IF(G27=T29,W29,W30))) -> 13418 | R27: ADDITEL | S27: 681 | T27: 211H200A0024 | U27: 46006 | V27: (0 a 3000) psi | W27: 13391 | X27: FLEXILATINA | Z27: TESTO | AA27: 622 | AB27: 39536692/0323 | AC27: 45695 | AD27: (-20 a 60) °C / (0 a 100) %hr | AE27: HR-4914-25 / TE-8606-25 | AF27: VALMET L&M
C28: TERMOHIGRÓMETRO | D28: =IF('DATOS INCERTIDUMBRE'!G4="Kex",'CALIBRACIÓN PSV'!Z29,'CALIBRACIÓN PSV'!Z27) -> TESTO | E28: =IF('DATOS INCERTIDUMBRE'!G4="Kex",'CALIBRACIÓN PSV'!AA29,'CALIBRACIÓN PSV'!AA27) -> 622 | G28: =IF('DATOS INCERTIDUMBRE'!G4="Kex",'CALIBRACIÓN PSV'!AB29,'CALIBRACIÓN PSV'!AB27) -> 39536692/0323 | H28: =IF('DATOS INCERTIDUMBRE'!G4="Kex",'CALIBRACIÓN PSV'!AF29,'CALIBRACIÓN PSV'!AF27) -> VALMET L&M | K28: =IF('DATOS INCERTIDUMBRE'!G4="Kex",'CALIBRACIÓN PSV'!AD29,'CALIBRACIÓN PSV'!AD27) -> (-20 a 60) °C / (0 a 100) %hr | L28: =IF('DATOS INCERTIDUMBRE'!G4="Kex",'CALIBRACIÓN PSV'!AC29,'CALIBRACIÓN PSV'!AC27) -> 45695 | N28: =IF('DATOS INCERTIDUMBRE'!G4="Kex",'CALIBRACIÓN PSV'!AE29,'CALIBRACIÓN PSV'!AE27) -> HR-4914-25 / TE-8606-25 | R28: CRYSTAL | S28: XP2I | T28: 104696 | U28: 46006 | V28: (0 a 5000) psi | W28: 13390 | X28: FLEXILATINA | AC28: 45793 | AD28: (300 a 1200) hPa | AE28: MET-LP-CC 12662 | AF28: METROLABOR
H29: =IF('DATOS INCERTIDUMBRE'!G4="Kex",'CALIBRACIÓN PSV'!AF30,'CALIBRACIÓN PSV'!AF28) -> METROLABOR | K29: =IF('DATOS INCERTIDUMBRE'!G4="Kex",'CALIBRACIÓN PSV'!AD30,'CALIBRACIÓN PSV'!AD28) -> (300 a 1200) hPa | L29: =IF('DATOS INCERTIDUMBRE'!G4="Kex",'CALIBRACIÓN PSV'!AC30,'CALIBRACIÓN PSV'!AC28) -> 45793 | N29: =IF('DATOS INCERTIDUMBRE'!G4="Kex",'CALIBRACIÓN PSV'!AE30,'CALIBRACIÓN PSV'!AE28) -> MET-LP-CC 12662 | R29: CRYSTAL | S29: XP2I | T29: 322944 | U29: 45775 | V29: (0 a 1000) psi | W29: 12652 | X29: FLEXILATINA | Z29: KEX GERMANY | AA29: SH-172 | AB29: 50898 | AC29: 45798 | AD29: (10 a 90) %hr | AE29: HR-28703 | AF29: FYH
R30: WIKA | S30: CPG1500 | T30: 1A047Q87N2E | U30: 46020 | V30: (0 a 1000) psi | W30: 13418 | X30: FLEXILATINA | AC30: 45798 | AD30: (-50 a 70) °C | AE30: TA-28702 | AF30: FYH
C31: Nota: Las mediciones realizadas por VALSER S.A.S son trazables metrológicamente al SI a través de laboratorios de calibración acreditados por organismos de acreditación firmantes de acuerdos de reconocimiento mutuo.
R33: NITRÓGENO | S33: SÍ | T33: ASME I
B34: SECCIÓN 5. INFORMACIÓN DE FUNCIONAMIENTO | R34: AIRE | S34: NO | T34: ASME VIII
R35: GAS
C36: SELLADO: | F36: NORMA APLICABLE: | L36: ERROR MÁXIMO: | N36: =IF(AND(H36="ASME I",AND(L22>=15,L22<=70)),S42,IF(AND(H36="ASME I",AND(L22>70,L22<=300)),S43,IF(AND(H36="ASME I",AND(L22>300,L22<=1000)),S44,IF(AND(H36="ASME I",L22>1000),S45,IF(AND(H36="ASME VIII",AND(L22>=15,L22<=70)),U42,IF(AND(H36="ASME VIII",L22>70),U43,"-")))))) -> - | R36: AGUA
C38: REQUIERE AJUSTE: | F38: VALOR ANTES DE AJUSTE: | K38: =N22 -> psi | L38: FLUIDO DE PRUEBA:
B40: SECCIÓN 6: CONDICIONES AMBIENTALES REGISTRADAS | R40: ASME I | T40: ASME VIII
R41: RANGO PRESIÓN | S41: TOLERANCIA | T41: RANGO PRESIÓN | U41: TOLERANCIA
F42: MÍNIMA | J42: MÁXIMA | L42: UNIDADES | R42: 15-70 | S42: +-2 psi | T42: 15 - 70 PSI | U42: +-2 psi
C43: TEMPERATURA | F43: ='DATOS INCERTIDUMBRE'!C3 -> 0 | J43: ='DATOS INCERTIDUMBRE'!E3 -> 0 | L43: °C | R43: 70-300 | S43: +-3% DEL SET | T43: 70-3000 | U43: +-3% DEL SET
C44: HUMEDAD RELATIVA | F44: ='DATOS INCERTIDUMBRE'!C5 -> 0 | J44: ='DATOS INCERTIDUMBRE'!E5 -> 0 | L44: %hr | R44: 300-1000 | S44: +-10 psi
C45: PRESIÓN ATMOSFÉRICA | F45: ='DATOS INCERTIDUMBRE'!C4 -> 0 | J45: ='DATOS INCERTIDUMBRE'!E4 -> 0 | L45: hPa | R45: 1000 | S45: +-1% DEL SET
B47: SECCIÓN 7: RESULTADOS DE CALIBRACIÓN
D49: Presión de escape (Simmer) | G49: Incertidumbre | I49: UNIDADES | K49: DECLARACIÓN DE CONFORMIDAD | R49: Limite superior | S49: =IF(AND(H36="ASME I",AND(L22>=15,L22<=70)),L22+2,IF(AND(H36="ASME I",AND(L22>70,L22<=300)),L22+(L22*0.03),IF(AND(H36="ASME I",AND(L22>300,L22<=1000)),L22+10,IF(AND(H36="ASME I",L22>1000),L22+(L22*0.01),IF(AND(H36="ASME VIII",AND(L22>=15,L22<=70)),L22+2,IF(AND(H36="ASME VIII",L22>70),L22+(L22*0.03),"-")))))) -> - | T49: Incertidumbre máxima | U49: =ABS(ROUND(D50*0.01,1)) -> 0
D50: ='DATOS INCERTIDUMBRE'!D17 -> -0.0010705622 | G50: =+IF(AND(L22>860,'CÁLCULO INCERTIDUMBRE'!I2<0.9),0.9,'CÁLCULO INCERTIDUMBRE'!I2) -> 0.1822434 | I50: =N22 -> psi | K50: =IF(AND(D50<=S49,D50>=S50,G50<=U49),"CUMPLE","NO CUMPLE") -> NO CUMPLE | R50: Limite inferior | S50: =IF(AND(H36="ASME I",AND(L22>=15,L22<=70)),L22-2,IF(AND(H36="ASME I",AND(L22>70,L22<=300)),L22-(L22*0.03),IF(AND(H36="ASME I",AND(L22>300,L22<=1000)),L22-10,IF(AND(H36="ASME I",L22>1000),L22-(L22*0.01),IF(AND(H36="ASME VIII",AND(L22>=15,L22<=70)),L22-2,IF(AND(H36="ASME VIII",L22>70),L22-(L22*0.03),"-")))))) -> -
C52: =_xlfn.CONCAT("La incertidumbre de medición expandida reportada es evaluada como la incertidumbre estándar de la medida multiplicada por un factor de cobertura k = ",S52,", con una probabilidad de cobertura aproximadamente del 95 %." ) -> La incertidumbre de medición expandida reportada es evaluada como la incertidumbre estándar de la medida multiplicada por un factor de cobertura k = 2.03, con una probabilidad de cobertura aproximadamente del 95 %. | R52: k | S52: =ROUND(IF('DATOS INCERTIDUMBRE'!G3="Manómetro Crystal 1K",'CÁLCULO INCERTIDUMBRE'!E5,IF('DATOS INCERTIDUMBRE'!G3="Manómetro Crystal 5K",'CÁLCULO INCERTIDUMBRE'!E3,'CÁLCULO INCERTIDUMBRE'!E4)),2) -> 2.03
C54: =IF(H36="ASME VIII",_xlfn.CONCAT(T54,R55,T55),_xlfn.CONCAT(T54,R54,T55)) -> Los resultados de conformidad aplican para la presión de escape. La presión de escape no debe exceder la especificación establecida en ASME SEC. I parágrafo 72.2 de acuerdo con el set de presión tomado de la placa del fabricante. Adicionalmente, la incertidumbre de medición no debe ser mayor al ±1,0 % del valor medido, conforme a lo establecido en el numeral 1-3 de ASME PTC 25-2023. | R54: ASME SEC. I parágrafo 72.2 | T54: Los resultados de conformidad aplican para la presión de escape. La presión de escape no debe exceder la especificación establecida en
R55: ASME SEC VIII parágrafo UG-126 punto c | T55: de acuerdo con el set de presión tomado de la placa del fabricante. Adicionalmente, la incertidumbre de medición no debe ser mayor al ±1,0 % del valor medido, conforme a lo establecido en el numeral 1-3 de ASME PTC 25-2023.
B58: SECCIÓN 8: REPRESENTACIÓN GRÁFICA EN UNIDADES DEL EQUIPO | I58: SECCIÓN 9: GRÁFICA EMITIDA POR EL MANÓMETRO
B60: OBSERVACIONES: - Este certificado expresa fielmente el resultado de las mediciones realizadas. NO podrá ser reproducido total o parcialmente excepto cuando se haya obtenido previamente permiso por escrito del laboratorio que lo emite. - Los resultados del presente certificado se refieren al ítem, momento y condiciones en que se realizó la prueba, VALSER S.A.S. no se responsabiliza de los perjuicios que pueda ocasionar el uso inadecuado del servicio prestado. - La presión de escape corresponde al promedio de los 4 escapes registrados durante la calibración, evidenciados en la gráfica de la sección 8. - La conversión de unidades para pasar a unidades del SI (kPa= psi * 6,894 757) esta conversión es tomada según la guía NIST SP-811 del 2008 sección B.9 - Descargo de responsabilidad ajuste válvulas de seguridad: Con la aceptación del servicio de calibración de las válvulas de seguridad, se da por entendido que se autoriza el ajuste de la válvula para dejarla al set de presión indicado en la placa del equipo de acuerdo con lo establecido en el GON-FO-04 | S60: - Descargo de responsabilidad por cambio de set de presión: Por solicitud del cliente, se realiza la calibración y ajuste a una presión diferente a la indicada en la placa del fabricante. Por lo anterior VALSER S.A.S. no se hace responsable por este cambio. | T60: - Descargo de responsabilidad por válvula sin placa de identificación: Se realiza la calibración y ajuste de la válvula de seguridad a la presión indicada por el cliente, debido a que la válvula no tiene placa del fabricante. Por lo anterior VALSER S.A.S. no se hace responsable de esta información.
B61: - Descargo de responsabilidad por cambio de set de presión: Por solicitud del cliente, se realiza la calibración y ajuste a una presión diferente a la indicada en la placa del fabricante. Por lo anterior VALSER S.A.S. no se hace responsable por este cambio. | P61: DESCARGOS DE RESPONSABILIDAD
...

Sheet DATOS INCERTIDUMBRE
B2: Mínimo | D2: Máximo | F2: Datos de prueba
B3: Temperatura (°C) | C3: 0 | D3: Temperatura (°C) | E3: 0 | F3: Manometro | G3: Manómetro Wika | I3: Manómetro Crystal 5K | K3: Grafica
B4: Presión atmosferica (hPa) | C4: 0 | D4: Presión atmosferica (hPa) | E4: 0 | F4: Termohigrometro | G4: Testo | I4: Manómetro Crystal 1K | K4: Punto | L4: Valor | M4: Incertidumbre | N4: EMP (arriba) | O4: EMP (arriba)
B5: Humedad relativa (%) | C5: 0 | D5: Humedad relativa (%) | E5: 0 | F5: Lugar de prueba | I5: Manómetro Additel | K5: 0 | L5: - | M5: - | N5: ='CALIBRACIÓN PSV'!$L$22+IF('CALIBRACIÓN PSV'!$H$36="ASME I",IF(AND('CALIBRACIÓN PSV'!$L$22<=70,'CALIBRACIÓN PSV'!$L$22>=15),2,IF(AND('CALIBRACIÓN PSV'!$L$22<=300,'CALIBRACIÓN PSV'!$L$22>70),'CALIBRACIÓN PSV'!$L$22*0.03,IF(AND('CALIBRACIÓN PSV'!$L$22<=1000,'CALIBRACIÓN PSV'!$L$22>300),10,IF('CALIBRACIÓN PSV'!$L$22>1000,'CALIBRACIÓN PSV'!$L$22*0.01)))),IF(AND('CALIBRACIÓN PSV'!$L$22<=70,'CALIBRACIÓN PSV'!$L$22>=15),2,IF('CALIBRACIÓN PSV'!$L$22>=70,'CALIBRACIÓN PSV'!$L$22*0.03,0))) -> 0 | O5: ='CALIBRACIÓN PSV'!$L$22-IF('CALIBRACIÓN PSV'!$H$36="ASME I",IF(AND('CALIBRACIÓN PSV'!$L$22<=70,'CALIBRACIÓN PSV'!$L$22>=15),2,IF(AND('CALIBRACIÓN PSV'!$L$22<=300,'CALIBRACIÓN PSV'!$L$22>70),'CALIBRACIÓN PSV'!$L$22*0.03,IF(AND('CALIBRACIÓN PSV'!$L$22<=1000,'CALIBRACIÓN PSV'!$L$22>300),10,IF('CALIBRACIÓN PSV'!$L$22>1000,'CALIBRACIÓN PSV'!$L$22*0.01)))),IF(AND('CALIBRACIÓN PSV'!$L$22<=70,'CALIBRACIÓN PSV'!$L$22>=15),2,IF('CALIBRACIÓN PSV'!$L$22>=70,'CALIBRACIÓN PSV'!$L$22*0.03,0))) -> 0
F6: Hora de prueba | I6: Manómetro Wika | K6: 1 | L6: =D10 -> -0.0010705622 | M6: =+IF(AND($L$22>860,'CÁLCULO INCERTIDUMBRE'!$I$2<0.9),0.9,'CÁLCULO INCERTIDUMBRE'!$I$2) -> 0.1822434 | N6: ='CALIBRACIÓN PSV'!$L$22+IF('CALIBRACIÓN PSV'!$H$36="ASME I",IF(AND('CALIBRACIÓN PSV'!$L$22<=70,'CALIBRACIÓN PSV'!$L$22>=15),2,IF(AND('CALIBRACIÓN PSV'!$L$22<=300,'CALIBRACIÓN PSV'!$L$22>70),'CALIBRACIÓN PSV'!$L$22*0.03,IF(AND('CALIBRACIÓN PSV'!$L$22<=1000,'CALIBRACIÓN PSV'!$L$22>300),10,IF('CALIBRACIÓN PSV'!$L$22>1000,'CALIBRACIÓN PSV'!$L$22*0.01)))),IF(AND('CALIBRACIÓN PSV'!$L$22<=70,'CALIBRACIÓN PSV'!$L$22>=15),2,IF('CALIBRACIÓN PSV'!$L$22>=70,'CALIBRACIÓN PSV'!$L$22*0.03,0))) -> 0 | O6: ='CALIBRACIÓN PSV'!$L$22-IF('CALIBRACIÓN PSV'!$H$36="ASME I",IF(AND('CALIBRACIÓN PSV'!$L$22<=70,'CALIBRACIÓN PSV'!$L$22>=15),2,IF(AND('CALIBRACIÓN PSV'!$L$22<=300,'CALIBRACIÓN PSV'!$L$22>70),'CALIBRACIÓN PSV'!$L$22*0.03,IF(AND('CALIBRACIÓN PSV'!$L$22<=1000,'CALIBRACIÓN PSV'!$L$22>300),10,IF('CALIBRACIÓN PSV'!$L$22>1000,'CALIBRACIÓN PSV'!$L$22*0.01)))),IF(AND('CALIBRACIÓN PSV'!$L$22<=70,'CALIBRACIÓN PSV'!$L$22>=15),2,IF('CALIBRACIÓN PSV'!$L$22>=70,'CALIBRACIÓN PSV'!$L$22*0.03,0))) -> 0
F7: Operario | K7: 2 | L7: =D11 -> -0.0010705622 | M7: =+IF(AND($L$22>860,'CÁLCULO INCERTIDUMBRE'!$I$2<0.9),0.9,'CÁLCULO INCERTIDUMBRE'!$I$2) -> 0.1822434 | N7: ='CALIBRACIÓN PSV'!$L$22+IF('CALIBRACIÓN PSV'!$H$36="ASME I",IF(AND('CALIBRACIÓN PSV'!$L$22<=70,'CALIBRACIÓN PSV'!$L$22>=15),2,IF(AND('CALIBRACIÓN PSV'!$L$22<=300,'CALIBRACIÓN PSV'!$L$22>70),'CALIBRACIÓN PSV'!$L$22*0.03,IF(AND('CALIBRACIÓN PSV'!$L$22<=1000,'CALIBRACIÓN PSV'!$L$22>300),10,IF('CALIBRACIÓN PSV'!$L$22>1000,'CALIBRACIÓN PSV'!$L$22*0.01)))),IF(AND('CALIBRACIÓN PSV'!$L$22<=70,'CALIBRACIÓN PSV'!$L$22>=15),2,IF('CALIBRACIÓN PSV'!$L$22>=70,'CALIBRACIÓN PSV'!$L$22*0.03,0))) -> 0 | O7: ='CALIBRACIÓN PSV'!$L$22-IF('CALIBRACIÓN PSV'!$H$36="ASME I",IF(AND('CALIBRACIÓN PSV'!$L$22<=70,'CALIBRACIÓN PSV'!$L$22>=15),2,IF(AND('CALIBRACIÓN PSV'!$L$22<=300,'CALIBRACIÓN PSV'!$L$22>70),'CALIBRACIÓN PSV'!$L$22*0.03,IF(AND('CALIBRACIÓN PSV'!$L$22<=1000,'CALIBRACIÓN PSV'!$L$22>300),10,IF('CALIBRACIÓN PSV'!$L$22>1000,'CALIBRACIÓN PSV'!$L$22*0.01)))),IF(AND('CALIBRACIÓN PSV'!$L$22<=70,'CALIBRACIÓN PSV'!$L$22>=15),2,IF('CALIBRACIÓN PSV'!$L$22>=70,'CALIBRACIÓN PSV'!$L$22*0.03,0))) -> 0
B8: 1 | C8: Simmer (PSI) | D8: Simmer corregido (PSI) | I8: Testo | K8: 3 | L8: =D12 -> -0.0010705622 | M8: =+IF(AND($L$22>860,'CÁLCULO INCERTIDUMBRE'!$I$2<0.9),0.9,'CÁLCULO INCERTIDUMBRE'!$I$2) -> 0.1822434 | N8: ='CALIBRACIÓN PSV'!$L$22+IF('CALIBRACIÓN PSV'!$H$36="ASME I",IF(AND('CALIBRACIÓN PSV'!$L$22<=70,'CALIBRACIÓN PSV'!$L$22>=15),2,IF(AND('CALIBRACIÓN PSV'!$L$22<=300,'CALIBRACIÓN PSV'!$L$22>70),'CALIBRACIÓN PSV'!$L$22*0.03,IF(AND('CALIBRACIÓN PSV'!$L$22<=1000,'CALIBRACIÓN PSV'!$L$22>300),10,IF('CALIBRACIÓN PSV'!$L$22>1000,'CALIBRACIÓN PSV'!$L$22*0.01)))),IF(AND('CALIBRACIÓN PSV'!$L$22<=70,'CALIBRACIÓN PSV'!$L$22>=15),2,IF('CALIBRACIÓN PSV'!$L$22>=70,'CALIBRACIÓN PSV'!$L$22*0.03,0))) -> 0 | O8: ='CALIBRACIÓN PSV'!$L$22-IF('CALIBRACIÓN PSV'!$H$36="ASME I",IF(AND('CALIBRACIÓN PSV'!$L$22<=70,'CALIBRACIÓN PSV'!$L$22>=15),2,IF(AND('CALIBRACIÓN PSV'!$L$22<=300,'CALIBRACIÓN PSV'!$L$22>70),'CALIBRACIÓN PSV'!$L$22*0.03,IF(AND('CALIBRACIÓN PSV'!$L$22<=1000,'CALIBRACIÓN PSV'!$L$22>300),10,IF('CALIBRACIÓN PSV'!$L$22>1000,'CALIBRACIÓN PSV'!$L$22*0.01)))),IF(AND('CALIBRACIÓN PSV'!$L$22<=70,'CALIBRACIÓN PSV'!$L$22>=15),2,IF('CALIBRACIÓN PSV'!$L$22>=70,'CALIBRACIÓN PSV'!$L$22*0.03,0))) -> 0
B9: Datos | C9: Presión de escape | D9: Presión de escape | I9: Kex | K9: 4 | L9: =D13 -> -0.0010705622 | M9: =+IF(AND($L$22>860,'CÁLCULO INCERTIDUMBRE'!$I$2<0.9),0.9,'CÁLCULO INCERTIDUMBRE'!$I$2) -> 0.1822434 | N9: ='CALIBRACIÓN PSV'!$L$22+IF('CALIBRACIÓN PSV'!$H$36="ASME I",IF(AND('CALIBRACIÓN PSV'!$L$22<=70,'CALIBRACIÓN PSV'!$L$22>=15),2,IF(AND('CALIBRACIÓN PSV'!$L$22<=300,'CALIBRACIÓN PSV'!$L$22>70),'CALIBRACIÓN PSV'!$L$22*0.03,IF(AND('CALIBRACIÓN PSV'!$L$22<=1000,'CALIBRACIÓN PSV'!$L$22>300),10,IF('CALIBRACIÓN PSV'!$L$22>1000,'CALIBRACIÓN PSV'!$L$22*0.01)))),IF(AND('CALIBRACIÓN PSV'!$L$22<=70,'CALIBRACIÓN PSV'!$L$22>=15),2,IF('CALIBRACIÓN PSV'!$L$22>=70,'CALIBRACIÓN PSV'!$L$22*0.03,0))) -> 0 | O9: ='CALIBRACIÓN PSV'!$L$22-IF('CALIBRACIÓN PSV'!$H$36="ASME I",IF(AND('CALIBRACIÓN PSV'!$L$22<=70,'CALIBRACIÓN PSV'!$L$22>=15),2,IF(AND('CALIBRACIÓN PSV'!$L$22<=300,'CALIBRACIÓN PSV'!$L$22>70),'CALIBRACIÓN PSV'!$L$22*0.03,IF(AND('CALIBRACIÓN PSV'!$L$22<=1000,'CALIBRACIÓN PSV'!$L$22>300),10,IF('CALIBRACIÓN PSV'!$L$22>1000,'CALIBRACIÓN PSV'!$L$22*0.01)))),IF(AND('CALIBRACIÓN PSV'!$L$22<=70,'CALIBRACIÓN PSV'!$L$22>=15),2,IF('CALIBRACIÓN PSV'!$L$22>=70,'CALIBRACIÓN PSV'!$L$22*0.03,0))) -> 0
B10: 1 | C10: 0 | D10: =C10+IF($G$3="Manómetro Crystal 5K",(4.1126295492E-20*(C10^6))-(4.36746502689345E-16*(C10^5))+(1.77384447618266E-12*(C10^4))-(3.42850808478409E-09*(C10^3))+(3.19285876475631E-06*(C10^2))-(0.00118466966428876*C10)-0.00224021406603825,IF($G$3="Manómetro Crystal 1K",((-8.734071321816E-18*(C10^6))+(3.69940365616324E-14*(C10^5))-(5.88687874755048E-11*(C10^4))+(4.34004268789643E-08*(C10^3))-(0.000014556750777453*(C10^2))+(0.00193523545422192*C10)+0.0158504394420191),IF($G$3="Manómetro Additel",(3.1782092705E-20*(C10^6))-(2.86096661253844E-16*(C10^5))+(9.60090252083449E-13*(C10^4))-(1.4836172572118E-09*(C10^3))+(1.04004189668827E-06*(C10^2))-(0.000448993805870046*C10)-0.000818552659893612,(-5.987586408792E-18*(C10^6))+(2.14463810734081E-14*(C10^5))-(2.90929335535737E-11*(C10^4))+(1.78147682184933E-08*(C10^3))-(4.50989019522979E-06*(C10^2))+(0.000385811685473136*C10)-0.00107056218167401))) -> -0.0010705622 | K10: 5 | L10: - | M10: - | N10: ='CALIBRACIÓN PSV'!$L$22+IF('CALIBRACIÓN PSV'!$H$36="ASME I",IF(AND('CALIBRACIÓN PSV'!$L$22<=70,'CALIBRACIÓN PSV'!$L$22>=15),2,IF(AND('CALIBRACIÓN PSV'!$L$22<=300,'CALIBRACIÓN PSV'!$L$22>70),'CALIBRACIÓN PSV'!$L$22*0.03,IF(AND('CALIBRACIÓN PSV'!$L$22<=1000,'CALIBRACIÓN PSV'!$L$22>300),10,IF('CALIBRACIÓN PSV'!$L$22>1000,'CALIBRACIÓN PSV'!$L$22*0.01)))),IF(AND('CALIBRACIÓN PSV'!$L$22<=70,'CALIBRACIÓN PSV'!$L$22>=15),2,IF('CALIBRACIÓN PSV'!$L$22>=70,'CALIBRACIÓN PSV'!$L$22*0.03,0))) -> 0 | O10: ='CALIBRACIÓN PSV'!$L$22-IF('CALIBRACIÓN PSV'!$H$36="ASME I",IF(AND('CALIBRACIÓN PSV'!$L$22<=70,'CALIBRACIÓN PSV'!$L$22>=15),2,IF(AND('CALIBRACIÓN PSV'!$L$22<=300,'CALIBRACIÓN PSV'!$L$22>70),'CALIBRACIÓN PSV'!$L$22*0.03,IF(AND('CALIBRACIÓN PSV'!$L$22<=1000,'CALIBRACIÓN PSV'!$L$22>300),10,IF('CALIBRACIÓN PSV'!$L$22>1000,'CALIBRACIÓN PSV'!$L$22*0.01)))),IF(AND('CALIBRACIÓN PSV'!$L$22<=70,'CALIBRACIÓN PSV'!$L$22>=15),2,IF('CALIBRACIÓN PSV'!$L$22>=70,'CALIBRACIÓN PSV'!$L$22*0.03,0))) -> 0
B11: 2 | C11: 0 | D11: =C11+IF($G$3="Manómetro Crystal 5K",(4.1126295492E-20*(C11^6))-(4.36746502689345E-16*(C11^5))+(1.77384447618266E-12*(C11^4))-(3.42850808478409E-09*(C11^3))+(3.19285876475631E-06*(C11^2))-(0.00118466966428876*C11)-0.00224021406603825,IF($G$3="Manómetro Crystal 1K",((-8.734071321816E-18*(C11^6))+(3.69940365616324E-14*(C11^5))-(5.88687874755048E-11*(C11^4))+(4.34004268789643E-08*(C11^3))-(0.000014556750777453*(C11^2))+(0.00193523545422192*C11)+0.0158504394420191),IF($G$3="Manómetro Additel",(3.1782092705E-20*(C11^6))-(2.86096661253844E-16*(C11^5))+(9.60090252083449E-13*(C11^4))-(1.4836172572118E-09*(C11^3))+(1.04004189668827E-06*(C11^2))-(0.000448993805870046*C11)-0.000818552659893612,(-5.987586408792E-18*(C11^6))+(2.14463810734081E-14*(C11^5))-(2.90929335535737E-11*(C11^4))+(1.78147682184933E-08*(C11^3))-(4.50989019522979E-06*(C11^2))+(0.000385811685473136*C11)-0.00107056218167401))) -> -0.0010705622
B12: 3 | C12: 0 | D12: =C12+IF($G$3="Manómetro Crystal 5K",(4.1126295492E-20*(C12^6))-(4.36746502689345E-16*(C12^5))+(1.77384447618266E-12*(C12^4))-(3.42850808478409E-09*(C12^3))+(3.19285876475631E-06*(C12^2))-(0.00118466966428876*C12)-0.00224021406603825,IF($G$3="Manómetro Crystal 1K",((-8.734071321816E-18*(C12^6))+(3.69940365616324E-14*(C12^5))-(5.88687874755048E-11*(C12^4))+(4.34004268789643E-08*(C12^3))-(0.000014556750777453*(C12^2))+(0.00193523545422192*C12)+0.0158504394420191),IF($G$3="Manómetro Additel",(3.1782092705E-20*(C12^6))-(2.86096661253844E-16*(C12^5))+(9.60090252083449E-13*(C12^4))-(1.4836172572118E-09*(C12^3))+(1.04004189668827E-06*(C12^2))-(0.000448993805870046*C12)-0.000818552659893612,(-5.987586408792E-18*(C12^6))+(2.14463810734081E-14*(C12^5))-(2.90929335535737E-11*(C12^4))+(1.78147682184933E-08*(C12^3))-(4.50989019522979E-06*(C12^2))+(0.000385811685473136*C12)-0.00107056218167401))) -> -0.0010705622 | Q12: NOTA: Insertar esta grafica en la hoja "CALIBRACIÓN PSV"
B13: 4 | C13: 0 | D13: =C13+IF($G$3="Manómetro Crystal 5K",(4.1126295492E-20*(C13^6))-(4.36746502689345E-16*(C13^5))+(1.77384447618266E-12*(C13^4))-(3.42850808478409E-09*(C13^3))+(3.19285876475631E-06*(C13^2))-(0.00118466966428876*C13)-0.00224021406603825,IF($G$3="Manómetro Crystal 1K",((-8.734071321816E-18*(C13^6))+(3.69940365616324E-14*(C13^5))-(5.88687874755048E-11*(C13^4))+(4.34004268789643E-08*(C13^3))-(0.000014556750777453*(C13^2))+(0.00193523545422192*C13)+0.0158504394420191),IF($G$3="Manómetro Additel",(3.1782092705E-20*(C13^6))-(2.86096661253844E-16*(C13^5))+(9.60090252083449E-13*(C13^4))-(1.4836172572118E-09*(C13^3))+(1.04004189668827E-06*(C13^2))-(0.000448993805870046*C13)-0.000818552659893612,(-5.987586408792E-18*(C13^6))+(2.14463810734081E-14*(C13^5))-(2.90929335535737E-11*(C13^4))+(1.78147682184933E-08*(C13^3))-(4.50989019522979E-06*(C13^2))+(0.000385811685473136*C13)-0.00107056218167401))) -> -0.0010705622
B15: Variación medidas
Q16: Tamaño alto = 5,7
B17: Promedio | C17: =AVERAGE(C10:C13) -> 0 | D17: =AVERAGE(D10:D13) -> -0.0010705622
B19: Datos | C19: =COUNT(C10:C13) -> 4

Sheet CÁLCULO INCERTIDUMBRE
B2: Manómetro | C2: u_Presión apertura | D2: Grados de libertad | E2: Factor de cobertura (k) | F2: U_Expandida | H2: U seleccionada | I2: =IF('DATOS INCERTIDUMBRE'!$G$3="Manómetro Crystal 5K",'CÁLCULO INCERTIDUMBRE'!$F$3,IF('DATOS INCERTIDUMBRE'!$G$3="Manómetro Crystal 1K",'CÁLCULO INCERTIDUMBRE'!$F$5,IF('DATOS INCERTIDUMBRE'!$G$3="Manómetro Additel",'CÁLCULO INCERTIDUMBRE'!$F$4,F6))) -> 0.1822434
B3: Manómetro Crystal 0-5000 psi | C3: =SQRT(SUMSQ(D29*F29,$C$50*$E$50,$M$27)) -> 0.19917267 | D3: =(C3^4)/((((D29*F29)^4)/E29)+((($C$50*$E$50)^4)/$D$50)+((($M$27)^4)/14)) -> 137.78221 | E3: =TINV(1-0.9545,D3) -> 2.018415 | F3: =E3*C3 -> 0.4020131
B4: Manómetro Additel 0-3000 psi | C4: =SQRT(SUMSQ(D30*F30,$C$50*$E$50,$M$27)) -> 0.29098772 | D4: =(C4^4)/((((D30*F30)^4)/E30)+((($C$50*$E$50)^4)/$D$50)+((($M$27)^4)/14)) -> 77.599903 | E4: =TINV(1-0.9545,D4) -> 2.0329929 | F4: =E4*C4 -> 0.59157598
B5: Manómetro Crystal 0-1000 psi | C5: =SQRT(SUMSQ(D31*F31,$C$50*$E$50,$M$27)) -> 0.088501238 | D5: =(C5^4)/((((D31*F31)^4)/E31)+((($C$50*$E$50)^4)/$D$50)+((($M$27)^4)/14)) -> 146.7727 | E5: =TINV(1-0.9545,D5) -> 2.0172704 | F5: =E5*C5 -> 0.17853093
B6: Manómetro Wika 0-1000 psi | C6: =SQRT(SUMSQ(D32*F32,$C$50*$E$50,$M$27)) -> 0.090346887 | D6: =(C6^4)/((((D32*F32)^4)/E32)+((($C$50*$E$50)^4)/$D$50)+((($M$27)^4)/14)) -> 147.10819 | E6: =TINV(1-0.9545,D6) -> 2.0171519 | F6: =E6*C6 -> 0.1822434
B8: Datos medidos | E8: Condiciones ambientales
B9: N | C9: Pm (psi) | E9: Humedad (%HR) | F9: ='DATOS INCERTIDUMBRE'!E5 -> 0
B10: 1 | C10: ='DATOS INCERTIDUMBRE'!D10 -> -0.0010705622 | E10: Temperatura (°C) | F10: ='DATOS INCERTIDUMBRE'!E3 -> 0
B11: 2 | C11: ='DATOS INCERTIDUMBRE'!D11 -> -0.0010705622 | E11: Presión atmosferica (hPa) | F11: ='DATOS INCERTIDUMBRE'!E4 -> 0
B12: 3 | C12: ='DATOS INCERTIDUMBRE'!D12 -> -0.0010705622
B13: 4 | C13: ='DATOS INCERTIDUMBRE'!D13 -> -0.0010705622
B14: Promedio | C14: =AVERAGE(C10:C13) -> -0.0010705622
B16: Datos ecuación 1 | D16: Resolución (psi) | E16: Deriva (psi) | F16: Interpolación (psi) | G16: Lectura (psi) | H16: Certificado (psi) | I16: Factor de cobertura | K16: Incertidumbre por operario (psi)
B17: Manómetro Crystal 0-5000 psi | D17: 0.1 | E17: 0.26 | F17: 0.011396482 | G17: =STDEV($C$10:$C$13) -> 0 | H17: 0.24 | I17: 2 | K17: Operario | L17: Datos | M17: Datos
B18: Manómetro Additel 0-3000 psi | D18: 0.1 | E18: 0.45 | F18: 0.012934978 | G18: =STDEV($C$10:$C$13) -> 0 | H18: 0.24 | I18: 2 | K18: Jonathan Garzón | L18: 65.08 | M18: =COUNT(L18:L32) -> 15
B19: Manómetro Crystal 0-1000 psi | D19: 0.1 | E19: 0.092 | F19: 0.016988097 | G19: =STDEV($C$10:$C$13) -> 0 | H19: 0.092 | I19: 2 | L19: 65.28 | M19: Desviación
B20: Manómetro Wika 0-1000 psi | D20: 0.1 | E20: 0.097 | F20: 0.0082119596 | G20: =STDEV($C$10:$C$13) -> 0 | H20: 0.097 | I20: 2 | L20: 65.08 | M20: =STDEV(L18:L32) -> 0.16308922
K21: Alexander Castro | L21: 65.01
B22: Magnitud | D22: u resolución (psi) | E22: u deriva (psi) | F22: u Interpolación (psi) | G22: u Lectura (psi) | H22: u certificado (psi) | I22: u combinada (psi) | L22: 65.16
B23: Manómetro Crystal 0-5000 psi | D23: =D17/SQRT(12) -> 0.028867513 | E23: =E17/SQRT(3) -> 0.15011107 | F23: =F17 -> 0.011396482 | G23: =G17/SQRT(COUNT(C10:C13)) -> 0 | H23: =H17/I17 -> 0.12 | I23: =SQRT(SUMSQ(D23:H23)) -> 0.19467035 | L23: 65.19
B24: Manómetro Additel 0-3000 psi | D24: =D18/SQRT(12) -> 0.028867513 | E24: =E18/SQRT(3) -> 0.25980762 | F24: =F18 -> 0.012934978 | G24: =G18/SQRT(COUNT(C10:C13)) -> 0 | H24: =H18/I18 -> 0.12 | I24: =SQRT(SUMSQ(D24:H24)) -> 0.28792472 | K24: Carlos Suarez | L24: 65.34
B25: Manómetro Crystal 0-1000 psi | D25: =D19/SQRT(12) -> 0.028867513 | E25: =E19/SQRT(3) -> 0.053116225 | F25: =F19 -> 0.016988097 | G25: =G19/SQRT(COUNT(C10:C13)) -> 0 | H25: =H19/I19 -> 0.046 | I25: =SQRT(SUMSQ(D25:H25)) -> 0.077841262 | L25: 65.16 | M25: Incertidumbre (psi)
B26: Manómetro Wika 0-1000 psi | D26: =D20/SQRT(12) -> 0.028867513 | E26: =E20/SQRT(3) -> 0.056002976 | F26: =F20 -> 0.0082119596 | G26: =G20/SQRT(COUNT(C11:C14)) -> 0 | H26: =H20/I20 -> 0.0485 | I26: =SQRT(SUMSQ(D26:H26)) -> 0.079933428 | L26: 64.86
K27: Brayan García | L27: 64.7 | M27: =M20/SQRT(M18) -> 0.042109457
B28: Magnitud | D28: U_Presión manómetro (Pm) (psi) | E28: Grados de libertad | F28: Coeficiente de sensibilidad | L28: 65.1
B29: Manómetro Crystal 0-5000 psi | D29: =I23 -> 0.19467035 | E29: =+(D29^4)/(((D23^4)/200)+((E23^4)/50)+((F23^4)/10)+((G23^4)/3)+((H23^4)/200)) -> 128.26209 | F29: 1 | L29: 65.23
B30: Manómetro Additel 0-3000 psi | D30: =I24 -> 0.28792472 | E30: =+(D30^4)/(((D24^4)/200)+((E24^4)/50)+((F24^4)/10)+((G24^4)/3)+((H24^4)/200)) -> 74.565054 | F30: 1 | K30: Heliodoro Prada | L30: 65.16
B31: Manómetro Crystal 0-1000 psi | D31: =I25 -> 0.077841262 | E31: =+(D31^4)/(((D25^4)/200)+((E25^4)/50)+((F25^4)/10)+((G25^4)/3)+((H25^4)/200)) -> 189.85102 | F31: 1 | L31: 65.06
B32: Manómetro Wika 0-1000 psi | D32: =I26 -> 0.079933428 | E32: =+(D32^4)/(((D26^4)/200)+((E26^4)/50)+((F26^4)/10)+((G26^4)/3)+((H26^4)/200)) -> 178.79771 | F32: 1 | L32: 64.96
B34: Datos ecuación 2 | D34: Resolución (m) | E34: Deriva (m) | F34: Suma de residuos - Interpolación (m) | G34: Certificado (m) | H34: Factor de cobertura (k)
B35: Flexómetro | D35: =1/1000 -> 0.001 | E35: =0.42/1000 -> 0.00042 | F35: =0.0367581286850754/1000 -> 3.6758129e-05 | G35: =0.42/1000 -> 0.00042 | H35: 2
K36: Para la densidad del aire
B37: Magnitud | C37: Valor | K37: Constantes | L37: Variables
B38: Densidad N2 (kg/m3) | C38: 0.97 | K38: 0.34848 | L38: Humedad | M38: =F9 -> 0 | N38: %hr
B39: Densidad aire (kg/m3) | C39: =((K38*M40)-(K39*M38)*EXP(K40*M39))/(K41+M39) -> 0 | K39: 0.009 | L39: Temperatura | M39: =F10 -> 0 | N39: °C
B40: Gravedad (m/s^2) | C40: 9.77 | K40: 0.061 | L40: Presión | M40: =F11 -> 0 | N40: hPa
B41: Altura (m) | C41: 0.45 | K41: 273.15
B43: Magnitud | C43: u resolución | D43: u deriva | E43: u Interpolación | F43: u certificado | G43: u combinada | H43: Coeficientes de sensibilidad | I43: Grados de libertad
B44: Densidad N2 (kg/m3) | C44: - | D44: - | E44: - | F44: - | G44: =C38*0.1/SQRT(12) -> 0.028001488 | H44: =C40*C41 -> 4.3965 | I44: =+(G44^4)/((G44^4)/200) -> 200
B45: Densidad aire (kg/m3) | C45: - | D45: - | E45: - | F45: - | G45: =B63 -> 0.0033082861 | H45: =C40*C41 -> 4.3965 | I45: =C63 -> 200.97199
...

Sheet CONTROL DE CAMBIOS
C1: INFORME DE CALIBRACIÓN DE VÁLVULA DE SEGURIDAD EN BANCO DE PRUEBAS
C3: CODIGO | D3: OHSQ-FO-43 | E3: VERSION | F3: 09 | G3: FECHA | H3: 46007
A5: CONTROL DE CAMBIOS
A7: FECHA | B7: VERSIÓN | C7: DESCRIPCIÓN | G7: AUTOR
A8: 45364 | B8: 1 | C8: Creación del documento | G8: Andres Felipe Ovalle Ortiz Asesor Comercial
A9: 45454 | B9: 2 | C9: Modificiacion por nuevo formato, cambio estructura | G9: Camilo Andres Fajardo Hoyos Asesor Comercial
A10: 45639 | B10: 3 | C10: Cambio de titulo documento | G10: Camilo Andres Fajardo Hoyos Asesor Comercial
A11: 45705 | B11: 4 | C11: Modificación del formato para cumplir la norma 17025, adición del cálculo de la incertidumbre | G11: Andres Felipe Ovalle Ortiz Asesor Comercial
A12: 45728 | B12: 5 | C12: Se agregan todas las incertidumbres | G12: Andres Felipe Ovalle Ortiz Asesor Comercial
A13: 45777 | B13: 6 | C13: Actualización del certificado, se agregan campos con mínimos y máximos de temperatura, se modifica todo el presupuesto de incertidumbre con el nuevo planteado y se agrega el nuevo manómetro utilizado. | G13: Andres Felipe Ovalle Ortiz Asesor Comercial
A14: 45891 | B14: 7 | C14: Actualización del documento, se complementa el método utilizado, se complementa el lugar de prueba, se realiza ajuste de redacción de la especificación y se modifica la redacción de los participantes en la calibración | G14: Andres Felipe Ovalle Ortiz Asesor Comercial
A15: 45917 | B15: 8 | C15: Actualización del documento con cambios de forma e incluyendo los descargos de responsabilidad | G15: Andres Felipe Ovalle Ortiz Asesor Comercial
A16: 46007 | B16: 9 | C16: Se actualiza el logo, para cambiarlo junto con el simbolo de acreditado ONAC | G16: Andres Felipe Ovalle Ortiz Líder de laboratorio
A19: CONTROL DE REVISIONES
A20: ELABORADO POR | C20: REVISADO POR | E20: APROBADO POR
A22: Nombre: | B22: Andres Felipe Ovalle Ortiz | C22: Nombre: | D22: Camilo Andrés Fajardo | E22: Nombre: | F22: Carlos Alberto Suarez Franco
A23: Cargo: | B23: Asesor Comercial | C23: Cargo: | D23: Asesor Comercial | E23: Cargo: | F23: Gerente General
A24: Fecha: | B24: 46007 | C24: Fecha: | D24: 46007 | E24: Fecha: | F24: 46007
