Workbook

Sheet CERTIFICADO
E1: CERTIFICADO DE CALIBRACIÓN EN LÍNEA DE VÁLVULA DE SEGURIDAD CON EQUIPO VST
E3: CÓDIGO | G3: OYS-FO-44 | I3: VERSIÓN | K3: 08 | L3: FECHA | N3: 46008
B4: SECCIÓN 1. INFORMACIÓN DEL LABORATORIO
C6: MÉTODO UTILIZADO: | E6: ASME PTC 25 - MÉTODO INDIRECTO | I6: FECHA DE RECEPCIÓN:
C8: LUGAR DE PRUEBA: | I8: FECHA DE CALIBRACIÓN: | R8: LABORATORIO VALSER
R9: INSTALACIONES DEL CLIENTE
C10: NÚMERO DE CERTIFICADO: | E10: CAL- | I10: FECHA DE EMISIÓN:
B12: SECCIÓN 2. INFORMACIÓN DEL CLIENTE
C14: CLIENTE: | G14: CONTACTO: | K14: CORREO:
B16: SECCIÓN 3. INFORMACIÓN VÁLVULA DE SEGURIDAD
C18: LOCALIZACIÓN: | J18: TAG: | L18: Nº PRECINTO:
C20: MARCA: | F20: TAMAÑO: | J20: CONEXIÓN ENTxSAL:
C22: MODELO: | F22: Nº SERIE: | J22: PRESIÓN CALIBRACIÓN: | N22: psi
T23: CELDAS DE CARGA | AC23: TRANSMISORES
C24: DIÁMETRO INTERNO: | D24: ='CÁLCULO INCERTIDUMBRE'!$F$24 -> 0 | E24: mm DIÁMETRO EXTERNO: | G24: ='CÁLCULO INCERTIDUMBRE'!$D$24 -> 0 | J24: mm | K24: ÁREA EFECTIVA: | L24: ='CÁLCULO INCERTIDUMBRE'!$C$4 -> 0 | N24: in²
T25: EQUIPO | U25: MARCA | V25: MODELO | W25: SERIAL | X25: FECHA DE CALIBRACIÓN | Y25: RANGO | Z25: CERTIFICADO | AA25: CERTIFICADOR | AC25: EQUIPO | AD25: MARCA | AE25: MODELO | AF25: SERIAL | AG25: FECHA DE CALIBRACIÓN | AH25: RANGO | AI25: CERTIFICADO | AJ25: CERTIFICADOR
B26: SECCIÓN 4. PATRONES DE TRABAJO | T26: CEC-001 | U26: TRUMAX | V26: SA-1Klb | W26: J181015117 | X26: 45860 | Y26: (0 a 950) lb-f | Z26: 8642 | AA26: SERVINTEGRAL | AC26: TP-010 | AD26: RITHERM | AE26: 3000 | AF26: 2074023 | AG26: 45986 | AH26: (0 a 1000) psi | AI26: 13356 | AJ26: FLEXILATINA
T27: CEC-004 | U27: BBG | V27: TSC | W27: 810551 | X27: 45824 | Y27: (0 a 2200) lb-f | Z27: 8532 | AA27: SERVINTEGRAL | AC27: TP-002 | AD27: APLISENS | AE27: PCR-28 | AF27: 11121025 | AG27: 45897 | AH27: (0 a 5000) psi | AI27: 13031 | AJ27: FLEXILATINA
C28: EQUIPO | D28: MARCA | E28: MODELO | G28: SERIAL | H28: CALIBRADO POR | K28: RANGO | L28: FECHA CALIBRACIÓN | N28: N° DE CERTIFICADO | Q28: CELDA DE CARGA USADA | R28: CEC-005 | T28: CEC-003 | U28: TRUMAX | V28: SC-5Klb | W28: M190927007 | X28: 45824 | Y28: (0 a 5000) lb-f | Z28: 8533 | AA28: SERVINTEGRAL | AC28: TP-004 | AD28: DANFOSS | AE28: MBS3000 | AF28: 92833390 | AG28: 45919 | AH28: (0 a 145) psi | AI28: 13098 | AJ28: FLEXILATINA
C29: CELDA DE CARGA | D29: =IF($R$28="CEC-004",U27,IF($R$28="CEC-003",U28,IF($R$28="CEC-005",U29,IF($R$28="CEC-007",U31,IF($R$28="CEC-001",U26,U30))))) -> TRUMAX | E29: =IF($R$28="CEC-004",V27,IF($R$28="CEC-003",V28,IF($R$28="CEC-005",V29,IF($R$28="CEC-007",V31,IF($R$28="CEC-001",V26,V30))))) -> SC-2.5Klb | G29: =IF($R$28="CEC-004",W27,IF($R$28="CEC-003",W28,IF($R$28="CEC-005",W29,IF($R$28="CEC-007",W31,IF($R$28="CEC-001",W26,W30))))) -> 2301129900 | H29: =IF($R$28="CEC-004",AA27,IF($R$28="CEC-003",AA28,IF($R$28="CEC-005",AA29,IF($R$28="CEC-007",AA31,IF($R$28="CEC-001",AA26,AA30))))) -> SERVINTEGRAL | K29: =IF($R$28="CEC-004",Y27,IF($R$28="CEC-003",Y28,IF($R$28="CEC-005",Y29,IF($R$28="CEC-007",Y31,IF($R$28="CEC-001",Y26,Y30))))) -> (0 a 2500) lb-f | L29: =IF($R$28="CEC-004",X27,IF($R$28="CEC-003",X28,IF($R$28="CEC-005",X29,IF($R$28="CEC-007",X31,IF($R$28="CEC-001",X26,X30))))) -> 45786 | N29: =IF($R$28="CEC-004",Z27,IF($R$28="CEC-003",Z28,IF($R$28="CEC-005",Z29,IF($R$28="CEC-007",Z31,IF($R$28="CEC-001",Z26,Z30))))) -> 8472 | T29: CEC-005 | U29: TRUMAX | V29: SC-2.5Klb | W29: 2301129900 | X29: 45786 | Y29: (0 a 2500) lb-f | Z29: 8472 | AA29: SERVINTEGRAL | AC29: TP-008 | AD29: DANFOSS | AE29: MBS3000 | AF29: 051950519282 | AG29: 45901 | AH29: (0 a 870) psi | AI29: 13029 | AJ29: FLEXILATINA
C30: TRANSMISOR DE PRESIÓN | D30: =IF($R$31="TP-010",AD26,IF($R$31="TP-002",AD27,IF($R$31="TP-004",AD28,IF($R$31="TP-009",AD30,AD29)))) -> DANFOSS | E30: =IF($R$31="TP-010",AE26,IF($R$31="TP-002",AE27,IF($R$31="TP-004",AE28,IF($R$31="TP-009",AE30,AE29)))) -> MBS3000 | G30: =IF($R$31="TP-010",AF26,IF($R$31="TP-002",AF27,IF($R$31="TP-004",AF28,IF($R$31="TP-009",AF30,AF29)))) -> 20275210 | H30: =IF($R$31="TP-010",AJ26,IF($R$31="TP-002",AJ27,IF($R$31="TP-004",AJ28,IF($R$31="TP-009",AJ30,AJ29)))) -> FLEXILATINA | K30: =IF($R$31="TP-010",AH26,IF($R$31="TP-002",AH27,IF($R$31="TP-004",AH28,IF($R$31="TP-009",AH30,AH29)))) -> (0 a 3625) psi | L30: =IF($R$31="TP-010",AG26,IF($R$31="TP-002",AG27,IF($R$31="TP-004",AG28,IF($R$31="TP-009",AG30,AG29)))) -> 45897 | N30: =IF($R$31="TP-010",AI26,IF($R$31="TP-002",AI27,IF($R$31="TP-004",AI28,IF($R$31="TP-009",AI30,AI29)))) -> 13030 | T30: CEC-006 | U30: TEK | V30: 516 2T | W30: 17080195 | X30: 45824 | Y30: (0 a 4400) lb-f | Z30: 8531 | AA30: SERVINTEGRAL | AC30: TP-009 | AD30: DANFOSS | AE30: MBS3000 | AF30: 20275210 | AG30: 45897 | AH30: (0 a 3625) psi | AI30: 13030 | AJ30: FLEXILATINA
C31: TERMOHIGRÓMETRO | D31: =IF(R37="TESTO",U35,U37) -> TESTO | E31: =IF(R37="TESTO",V35,V37) -> 622 | G31: =IF(R37="TESTO",W35,W37) -> 39536692/0323 | H31: =IF(R37="TESTO",AA35,AA37) -> VALMET L&M | K31: =IF(R37="TESTO",Y35,Y37) -> (-20 a 60) °C / (0 a 100) %hr | L31: =IF(R37="TESTO",X35,X37) -> 45695 | N31: =IF(R37="TESTO",Z35,Z37) -> HR-4914-25 / TE-8606-25 | Q31: TRANSMISOR USADO | R31: TP-009 | T31: CEC-007 | U31: TRUMAX | V31: SG-5T | W31: 2309210270 | X31: 46006 | Y31: (0 a 9920) lb-f | Z31: 8950 | AA31: SERVINTEGRAL
H32: =IF(R37="TESTO",AA36,AA38) -> METROLABOR | K32: =IF(R37="TESTO",Y36,Y38) -> (300 a 1200) hPa | L32: =IF(R37="TESTO",X36,X38) -> 45793 | N32: =IF(R37="TESTO",Z36,Z38) -> MET-LP-CC 12662
C33: PIE DE REY | D33: =IF(R34="INSIZE",AD35,AD36) -> INSIZE | E33: =IF(R34="INSIZE",AE35,AE36) -> 1108-200 | G33: =IF(R34="INSIZE",AF35,AF36) -> 1212181369 | H33: =IF($R$34="INSIZE",AJ35,AJ36) -> METROTEST | K33: =IF(R34="INSIZE",AH35,AH36) -> (0 a 200) mm | L33: =IF($R$34="INSIZE",AG35,AG36) -> 45796 | N33: =IF($R$34="INSIZE",AI35,AI36) -> CD-10088 | U33: TERMOHIGROMETRO | AC33: PIE DE REY
C34: CINTA MÉTRICA | D34: =AD41 -> TRUPER | E34: =AE41 -> FH-5M | G34: =AF41 -> UK 0126 0022 | H34: =AJ41 -> METROTEST | K34: =AH41 -> (0 a 5) m | L34: =AG41 -> 45796 | N34: =AI41 -> CD-10090 | Q34: PIE DE REY USADO | R34: INSIZE | U34: MARCA | V34: MODELO | W34: SERIAL | X34: FECHA DE CALIBRACIÓN | Y34: RANGO | Z34: CERTIFICADO | AA34: CERTIFICADOR | AC34: EQUIPO | AD34: MARCA | AE34: MODELO | AF34: SERIAL | AG34: FECHA DE CALIBRACIÓN | AH34: RANGO | AI34: CERTIFICADO | AJ34: CERTIFICADOR
U35: TESTO | V35: 622 | W35: 39536692/0323 | X35: 45695 | Y35: (-20 a 60) °C / (0 a 100) %hr | Z35: HR-4914-25 / TE-8606-25 | AA35: VALMET L&M | AC35: PDR-001 | AD35: INSIZE | AE35: 1108-200 | AF35: 1212181369 | AG35: 45796 | AH35: (0 a 200) mm | AI35: CD-10088 | AJ35: METROTEST
C36: Nota: Las mediciones realizadas por VALSER S.A.S son trazables metrológicamente al SI a través de laboratorios de calibración acreditados por organismos de acreditación firmantes de acuerdos de reconocimiento mutuo | X36: 45793 | Y36: (300 a 1200) hPa | Z36: MET-LP-CC 12662 | AA36: METROLABOR | AC36: PDR-002 | AD36: MITUTOYO | AE36: CD-6" CSX-B | AF36: BH010822 | AG36: 45796 | AH36: (0 a 150) mm | AI36: CD-10089 | AJ36: METROTEST
Q37: TERMOHIGROMETRO USADO | R37: TESTO | U37: KEX GERMANY | V37: SH-172 | W37: 50898 | X37: 45798 | Y37: (10 a 90) %hr | Z37: HR-28703 | AA37: FYH
X38: 45798 | Y38: (-50 a 70) °C | Z38: TA-28702 | AA38: FYH
B39: SECCIÓN 5. INFORMACIÓN DE FUNCIONAMIENTO | AC39: FLEXÓMETRO
AC40: EQUIPO | AD40: MARCA | AE40: MODELO | AF40: SERIAL | AG40: FECHA DE CALIBRACIÓN | AH40: RANGO | AI40: CERTIFICADO | AJ40: CERTIFICADOR
C41: SELLADO: | F41: NORMA APLICABLE: | L41: ERROR MÁXIMO: | N41: =IF(AND(H41="ASME I",AND(L22>15,L22<=70)),T43,IF(AND(H41="ASME I",AND(L22>70,L22<=300)),T44,IF(AND(H41="ASME I",AND(L22>300,L22<=1000)),T45,IF(AND(H41="ASME I",L22>1000),T46,IF(AND(H41="ASME VIII",AND(L22>15,L22<=70)),V43,IF(AND(H41="ASME VIII",L22>70),V44,"-")))))) -> - | Q41: SÍ | R41: ASME I | S41: ASME I | U41: ASME VIII | W41: VAPOR | AC41: FLX-001 | AD41: TRUPER | AE41: FH-5M | AF41: UK 0126 0022 | AG41: 45796 | AH41: (0 a 5) m | AI41: CD-10090 | AJ41: METROTEST
C42: REQUIERE AJUSTE: | F42: VALOR ANTES DE AJUSTE: | K42: =N22 -> psi | L42: FLUIDO DE PRUEBA: | Q42: NO | R42: ASME VIII | S42: RANGO PRESIÓN | T42: TOLERANCIA | U42: RANGO PRESIÓN | V42: TOLERANCIA | W42: NITRÓGENO
S43: 15-70 | T43: ± 2 psi | U43: 15 - 70 PSI | V43: ± 2 psi
B44: SECCIÓN 6: CONDICIONES AMBIENTALES REGISTRADAS | S44: 70-300 | T44: ± 3% DEL SET | U44: 70-3000 | V44: ± 3% DEL SET
S45: 300-1000 | T45: ± 10 psi
F46: MÍNIMA | J46: MÁXIMA | L46: UNIDADES | S46: 1000 | T46: ± 1% DEL SET
C47: TEMPERATURA | F47: ='DATOS INCERTIDUMBRE'!C3 -> 0 | J47: ='DATOS INCERTIDUMBRE'!E3 -> 0 | L47: °C
C48: HUMEDAD RELATIVA | F48: ='DATOS INCERTIDUMBRE'!C5 -> 0 | J48: ='DATOS INCERTIDUMBRE'!E5 -> 0 | L48: %hr
C49: PRESIÓN ATMOSFÉRICA | F49: ='DATOS INCERTIDUMBRE'!C4 -> 0 | J49: ='DATOS INCERTIDUMBRE'!E4 -> 0 | L49: hPa
...

Sheet DATOS INCERTIDUMBRE
B2: Minimos | D2: Máximos | F2: Datos de prueba | H2: Datos del vapor | L2: Grafica
B3: Temperatura (°C) | C3: 0 | D3: Temperatura (°C) | E3: 0 | F3: Transmisor | G3: - | H3: Presión (psi) | I3: 0 | L3: Punto | M3: Valor | N3: Incertidumbre | O3: EMP (arriba) | P3: EMP (abajo)
B4: Presión atmosferica (hPa) | C4: 0 | D4: Presión atmosferica (hPa) | E4: 0 | F4: Celda de carga | G4: - | H4: Temperatura (°C) | I4: 0 | L4: 0 | M4: - | N4: - | O4: =CERTIFICADO!$L$22+IF(CERTIFICADO!$H$41="ASME I",IF(AND(CERTIFICADO!$L$22<=70,CERTIFICADO!$L$22>=15),2,IF(AND(CERTIFICADO!$L$22<=300,CERTIFICADO!$L$22>70),CERTIFICADO!$L$22*0.03,IF(AND(CERTIFICADO!$L$22<=1000,CERTIFICADO!$L$22>300),10,IF(CERTIFICADO!$L$22>1000,CERTIFICADO!$L$22*0.01)))),IF(AND(CERTIFICADO!$L$22<=70,CERTIFICADO!$L$22>=15),2,IF(CERTIFICADO!$L$22>70,CERTIFICADO!$L$22*0.03,0))) -> 0 | P4: =CERTIFICADO!$L$22-IF(CERTIFICADO!$H$41="ASME I",IF(AND(CERTIFICADO!$L$22<=70,CERTIFICADO!$L$22>=15),2,IF(AND(CERTIFICADO!$L$22<=300,CERTIFICADO!$L$22>70),CERTIFICADO!$L$22*0.03,IF(AND(CERTIFICADO!$L$22<=1000,CERTIFICADO!$L$22>300),10,IF(CERTIFICADO!$L$22>1000,CERTIFICADO!$L$22*0.01)))),IF(AND(CERTIFICADO!$L$22<=70,CERTIFICADO!$L$22>=15),2,IF(CERTIFICADO!$L$22>70,CERTIFICADO!$L$22*0.03,0))) -> 0
B5: Humedad relativa (%) | C5: 0 | D5: Humedad relativa (%) | E5: 0 | F5: Lugar de prueba | H5: Volumen especifico | I5: 0 | L5: 1 | M5: =D11 -> 0 | N5: ='CÁLCULO INCERTIDUMBRE'!C8 -> #DIV/0! | O5: =CERTIFICADO!$L$22+IF(CERTIFICADO!$H$41="ASME I",IF(AND(CERTIFICADO!$L$22<=70,CERTIFICADO!$L$22>=15),2,IF(AND(CERTIFICADO!$L$22<=300,CERTIFICADO!$L$22>70),CERTIFICADO!$L$22*0.03,IF(AND(CERTIFICADO!$L$22<=1000,CERTIFICADO!$L$22>300),10,IF(CERTIFICADO!$L$22>1000,CERTIFICADO!$L$22*0.01)))),IF(AND(CERTIFICADO!$L$22<=70,CERTIFICADO!$L$22>=15),2,IF(CERTIFICADO!$L$22>70,CERTIFICADO!$L$22*0.03,0))) -> 0 | P5: =CERTIFICADO!$L$22-IF(CERTIFICADO!$H$41="ASME I",IF(AND(CERTIFICADO!$L$22<=70,CERTIFICADO!$L$22>=15),2,IF(AND(CERTIFICADO!$L$22<=300,CERTIFICADO!$L$22>70),CERTIFICADO!$L$22*0.03,IF(AND(CERTIFICADO!$L$22<=1000,CERTIFICADO!$L$22>300),10,IF(CERTIFICADO!$L$22>1000,CERTIFICADO!$L$22*0.01)))),IF(AND(CERTIFICADO!$L$22<=70,CERTIFICADO!$L$22>=15),2,IF(CERTIFICADO!$L$22>70,CERTIFICADO!$L$22*0.03,0))) -> 0
F6: Hora de prueba | L6: 2 | M6: =D12 -> 0 | N6: ='CÁLCULO INCERTIDUMBRE'!C8 -> #DIV/0! | O6: =CERTIFICADO!$L$22+IF(CERTIFICADO!$H$41="ASME I",IF(AND(CERTIFICADO!$L$22<=70,CERTIFICADO!$L$22>=15),2,IF(AND(CERTIFICADO!$L$22<=300,CERTIFICADO!$L$22>70),CERTIFICADO!$L$22*0.03,IF(AND(CERTIFICADO!$L$22<=1000,CERTIFICADO!$L$22>300),10,IF(CERTIFICADO!$L$22>1000,CERTIFICADO!$L$22*0.01)))),IF(AND(CERTIFICADO!$L$22<=70,CERTIFICADO!$L$22>=15),2,IF(CERTIFICADO!$L$22>70,CERTIFICADO!$L$22*0.03,0))) -> 0 | P6: =CERTIFICADO!$L$22-IF(CERTIFICADO!$H$41="ASME I",IF(AND(CERTIFICADO!$L$22<=70,CERTIFICADO!$L$22>=15),2,IF(AND(CERTIFICADO!$L$22<=300,CERTIFICADO!$L$22>70),CERTIFICADO!$L$22*0.03,IF(AND(CERTIFICADO!$L$22<=1000,CERTIFICADO!$L$22>300),10,IF(CERTIFICADO!$L$22>1000,CERTIFICADO!$L$22*0.01)))),IF(AND(CERTIFICADO!$L$22<=70,CERTIFICADO!$L$22>=15),2,IF(CERTIFICADO!$L$22>70,CERTIFICADO!$L$22*0.03,0))) -> 0
F7: Operario | L7: 3 | M7: =D13 -> 0 | N7: ='CÁLCULO INCERTIDUMBRE'!C8 -> #DIV/0! | O7: =CERTIFICADO!$L$22+IF(CERTIFICADO!$H$41="ASME I",IF(AND(CERTIFICADO!$L$22<=70,CERTIFICADO!$L$22>=15),2,IF(AND(CERTIFICADO!$L$22<=300,CERTIFICADO!$L$22>70),CERTIFICADO!$L$22*0.03,IF(AND(CERTIFICADO!$L$22<=1000,CERTIFICADO!$L$22>300),10,IF(CERTIFICADO!$L$22>1000,CERTIFICADO!$L$22*0.01)))),IF(AND(CERTIFICADO!$L$22<=70,CERTIFICADO!$L$22>=15),2,IF(CERTIFICADO!$L$22>70,CERTIFICADO!$L$22*0.03,0))) -> 0 | P7: =CERTIFICADO!$L$22-IF(CERTIFICADO!$H$41="ASME I",IF(AND(CERTIFICADO!$L$22<=70,CERTIFICADO!$L$22>=15),2,IF(AND(CERTIFICADO!$L$22<=300,CERTIFICADO!$L$22>70),CERTIFICADO!$L$22*0.03,IF(AND(CERTIFICADO!$L$22<=1000,CERTIFICADO!$L$22>300),10,IF(CERTIFICADO!$L$22>1000,CERTIFICADO!$L$22*0.01)))),IF(AND(CERTIFICADO!$L$22<=70,CERTIFICADO!$L$22>=15),2,IF(CERTIFICADO!$L$22>70,CERTIFICADO!$L$22*0.03,0))) -> 0
L8: 4 | M8: - | N8: - | O8: =CERTIFICADO!$L$22+IF(CERTIFICADO!$H$41="ASME I",IF(AND(CERTIFICADO!$L$22<=70,CERTIFICADO!$L$22>=15),2,IF(AND(CERTIFICADO!$L$22<=300,CERTIFICADO!$L$22>70),CERTIFICADO!$L$22*0.03,IF(AND(CERTIFICADO!$L$22<=1000,CERTIFICADO!$L$22>300),10,IF(CERTIFICADO!$L$22>1000,CERTIFICADO!$L$22*0.01)))),IF(AND(CERTIFICADO!$L$22<=70,CERTIFICADO!$L$22>=15),2,IF(CERTIFICADO!$L$22>70,CERTIFICADO!$L$22*0.03,0))) -> 0 | P8: =CERTIFICADO!$L$22-IF(CERTIFICADO!$H$41="ASME I",IF(AND(CERTIFICADO!$L$22<=70,CERTIFICADO!$L$22>=15),2,IF(AND(CERTIFICADO!$L$22<=300,CERTIFICADO!$L$22>70),CERTIFICADO!$L$22*0.03,IF(AND(CERTIFICADO!$L$22<=1000,CERTIFICADO!$L$22>300),10,IF(CERTIFICADO!$L$22>1000,CERTIFICADO!$L$22*0.01)))),IF(AND(CERTIFICADO!$L$22<=70,CERTIFICADO!$L$22>=15),2,IF(CERTIFICADO!$L$22>70,CERTIFICADO!$L$22*0.03,0))) -> 0
B9: 1 | C9: Simmer (PSI) | D9: Simmer corregido (PSI) | G9: Longitudes del pie de rey (mm) | J9: Temperatura en cada dato (°C)
B10: Datos | C10: Presión de escape | D10: Presión de escape | G10: Datos | H10: Diametro externo (L1) | I10: Diametro interno (L2)
B11: 1 | C11: 0 | D11: =C11 -> 0 | G11: 1 | H11: 0 | I11: 0 | J11: 0
B12: 2 | C12: 0 | D12: =C12 -> 0 | G12: 2 | H12: 0 | I12: 0 | J12: 0 | Q12: NOTA: Insertar esta grafica en la hoja "CALIBRACIÓN PSV"
B13: 3 | C13: 0 | D13: =C13 -> 0 | G13: 3 | H13: 0 | I13: 0 | J13: 0
G14: 4 | H14: 0 | I14: 0 | J14: 0
B15: Variación medidas | G15: 5 | H15: 0 | I15: 0 | J15: 0
G16: 6 | H16: 0 | I16: 0 | J16: 0 | Q16: Tamaño alto = 5,7
B17: Promedio | C17: =AVERAGE(C11:C14) -> 0 | D17: =AVERAGE(D11:D13) -> 0
H18: Presiones transmisor
B19: Datos | C19: =COUNT(C11:C14) -> 3 | H19: Datos | I19: Lectura (psi)
H20: 1 | I20: 0
H21: 2 | I21: 0
H22: 3 | I22: 0
H24: Altura (m) | I24: 0

Sheet CÁLCULO INCERTIDUMBRE
B2: Presión de set | C2: =I14 -> 0 | D2: psi | F2: Transmisor usado | G2: =IF(CERTIFICADO!$R$31="TP-010",$M$3,IF(CERTIFICADO!$R$31="TP-002",$M$4,IF(CERTIFICADO!$R$31="TP-004",$M$5,IF(CERTIFICADO!$R$31="TP-008",$M$6,IF(CERTIFICADO!$R$31="TP-009",$M$7,"ERROR"))))) -> VST 2 - 3625 | M2: Trasmisores | N2: Celdas
B3: Presión de caldera | C3: =C24 -> 0 | D3: psi | F3: Celda de carga usada | G3: =IF(CERTIFICADO!$R$28="CEC-001",$N$3,IF(CERTIFICADO!$R$28="CEC-004",$N$4,IF(CERTIFICADO!$R$28="CEC-003",$N$5,IF(CERTIFICADO!$R$28="CEC-005",$N$6,IF(CERTIFICADO!$R$28="CEC-006",$N$7,IF(CERTIFICADO!$R$28="CEC-007",$N$8,"ERROR")))))) -> VST 2 - 1T | M3: VST 1 - 1000 | N3: VST 1 - 0,5T
B4: Área | C4: =C96 -> 0 | D4: In^2 | M4: VST 1 - 5000 | N4: VST 1 - 1T
B5: Fuerza a realizar | C5: =(C2-C3)*C4 -> 0 | D5: Lb-f | M5: VST 2 - 145 | N5: VST 1 - 2T
M6: VST 2 - 870 | N6: VST 2 - 1T
B7: Factor de cobertura (K) | C7: Incertidumbre expandida (U) | M7: VST 2 - 3625 | N7: VST 2 - 2T
B8: =TINV(1-0.9545,E12) -> #DIV/0! | C8: =C12*B8 -> #DIV/0! | H8: Incertidumbre por repetibilidad | N8: VST 2 - 5T
H9: Datos medidos
B10: Resumen incertidumbre ecuación 1 | H10: N° | I10: Pm (psi) | J10: Desviación
B11: Magnitud | C11: Incertidumbre | D11: Coeficientes de sensibilidad | E11: Grados de libertad | F11: 1 | H11: 1 | I11: ='DATOS INCERTIDUMBRE'!D11 -> 0 | J11: =STDEV(I11:I13) -> 0
B12: P_apertura (psi) | C12: =SQRT(SUMSQ(C13*D13,C14*D14,J13)) -> #DIV/0! | D12: - | E12: =(C12^4)/((((C13*D13)^4)/E13)+(((C14*D14)^4)/E14)+((J13^4)/2)) -> #DIV/0! | H12: 2 | I12: ='DATOS INCERTIDUMBRE'!D12 -> 0 | J12: Incertidumbre
B13: P_indicada (psi) | C13: =B48 -> #DIV/0! | D13: =D48 -> 1 | E13: =C48 -> #DIV/0! | H13: 3 | I13: ='DATOS INCERTIDUMBRE'!D13 -> 0 | J13: =J11/SQRT(3) -> 0
B14: P_generada (psi) | C14: =C92 -> #DIV/0! | D14: =E92 -> 1 | E14: =D92 -> #DIV/0! | H14: Promedio | I14: =AVERAGE(I11:I13) -> 0
B16: Datos medidos | K16: Condiciones ambientales
B17: N | C17: Pt (psi) | D17: L1 (mm) | E17: L1 (m) | F17: L2 (mm) | G17: L2 (m) | H17: Tm (°C) | I17: To (°C) | K17: Humedad (%HR) | L17: ='DATOS INCERTIDUMBRE'!E5 -> 0
B18: 1 | C18: ='DATOS INCERTIDUMBRE'!I20 -> 0 | D18: ='DATOS INCERTIDUMBRE'!H11 -> 0 | E18: =D18/1000 -> 0 | F18: ='DATOS INCERTIDUMBRE'!I11 -> 0 | G18: =F18/1000 -> 0 | H18: ='DATOS INCERTIDUMBRE'!J11 -> 0 | I18: 20 | K18: Temperatura (°C) | L18: ='DATOS INCERTIDUMBRE'!E3 -> 0
B19: 2 | C19: ='DATOS INCERTIDUMBRE'!I21 -> 0 | D19: ='DATOS INCERTIDUMBRE'!H12 -> 0 | E19: =D19/1000 -> 0 | F19: ='DATOS INCERTIDUMBRE'!I12 -> 0 | G19: =F19/1000 -> 0 | H19: ='DATOS INCERTIDUMBRE'!J12 -> 0 | I19: 20 | K19: Presión atmosferica (hPa) | L19: ='DATOS INCERTIDUMBRE'!E4 -> 0
B20: 3 | C20: ='DATOS INCERTIDUMBRE'!I22 -> 0 | D20: ='DATOS INCERTIDUMBRE'!H13 -> 0 | E20: =D20/1000 -> 0 | F20: ='DATOS INCERTIDUMBRE'!I13 -> 0 | G20: =F20/1000 -> 0 | H20: ='DATOS INCERTIDUMBRE'!J13 -> 0 | I20: 20
B21: 4 | D21: ='DATOS INCERTIDUMBRE'!H14 -> 0 | E21: =D21/1000 -> 0 | F21: ='DATOS INCERTIDUMBRE'!I14 -> 0 | G21: =F21/1000 -> 0 | H21: ='DATOS INCERTIDUMBRE'!J14 -> 0 | I21: 20 | K21: Condiciones del vapor
B22: 5 | D22: ='DATOS INCERTIDUMBRE'!H15 -> 0 | E22: =D22/1000 -> 0 | F22: ='DATOS INCERTIDUMBRE'!I15 -> 0 | G22: =F22/1000 -> 0 | H22: ='DATOS INCERTIDUMBRE'!J15 -> 0 | I22: 20 | K22: Presión (psi) | L22: ='DATOS INCERTIDUMBRE'!I3 -> 0
B23: 6 | D23: ='DATOS INCERTIDUMBRE'!H16 -> 0 | E23: =D23/1000 -> 0 | F23: ='DATOS INCERTIDUMBRE'!I16 -> 0 | G23: =F23/1000 -> 0 | H23: ='DATOS INCERTIDUMBRE'!J16 -> 0 | I23: 20 | K23: Temperatura (°C) | L23: ='DATOS INCERTIDUMBRE'!I4 -> 0
B24: Promedio | C24: =AVERAGE(C18:C20) -> 0 | D24: =AVERAGE(D18:D23) -> 0 | E24: =AVERAGE(E18:E23) -> 0 | F24: =AVERAGE(F18:F23) -> 0 | G24: =AVERAGE(G18:G23) -> 0 | H24: =AVERAGE(H18:H23) -> 0 | I24: =AVERAGE(I18:I23) -> 20 | K24: Volumen especifico | L24: ='DATOS INCERTIDUMBRE'!I5 -> 0
B26: Datos ecuación 2 | D26: Resolución (psi) | E26: Deriva (psi) | F26: Suma de residuos - Interpolación | G26: Certificado (psi) | H26: Factor de cobertura
B27: Transmisor de presión VST1 - 1000 psi | D27: 0.01 | E27: 0.72 | F27: 0.29280805 | G27: 0.72 | H27: 2
B28: Transmisor de presión VST1 - 5000 psi | D28: 0.01 | E28: 1.4 | F28: 0.96784642 | G28: 1.4 | H28: 2
B29: Transmisor de presión VST2 - 145 psi | D29: 0.01 | E29: 0.05 | F29: 0.014776135 | G29: 0.048 | H29: 2
B30: Transmisor de presión VST2 - 870 psi | D30: 0.01 | E30: 0.1 | F30: 0.040148459 | G30: 0.07 | H30: 2
B31: Transmisor de presión VST2 - 3625 psi | D31: 0.01 | E31: 0.81 | F31: 0.52098775 | G31: 0.81 | H31: 2
B33: Magnitud | D33: u resolución (psi) | E33: u deriva (psi) | F33: u Interpolación (psi) | G33: u certificado (psi) | H33: u combinada (psi)
B34: Transmisor de presión VST1 - 1000 psi | D34: =D27/SQRT(12) -> 0.0028867513 | E34: =E27/SQRT(3) -> 0.41569219 | F34: =F27 -> 0.29280805 | G34: =G27/H27 -> 0.36 | H34: =SQRT(SUMSQ(D34:G34)) -> 0.62301275
B35: Transmisor de presión VST1 - 5000 psi | D35: =D28/SQRT(12) -> 0.0028867513 | E35: =E28/SQRT(3) -> 0.80829038 | F35: =F28 -> 0.96784642 | G35: =G28/H28 -> 0.7 | H35: =SQRT(SUMSQ(D35:G35)) -> 1.4422442
B36: Transmisor de presión VST2 - 145 psi | D36: =D29/SQRT(12) -> 0.0028867513 | E36: =E29/SQRT(3) -> 0.028867513 | F36: =F29 -> 0.014776135 | G36: =G29/H29 -> 0.024 | H36: =SQRT(SUMSQ(D36:G36)) -> 0.040447507
B37: Transmisor de presión VST2 - 870 psi | D37: =D30/SQRT(12) -> 0.0028867513 | E37: =E30/SQRT(3) -> 0.057735027 | F37: =F30 -> 0.040148459 | G37: =G30/H30 -> 0.035 | H37: =SQRT(SUMSQ(D37:G37)) -> 0.078603851
B38: Transmisor de presión VST2 - 3625 psi | D38: =D31/SQRT(12) -> 0.0028867513 | E38: =E31/SQRT(3) -> 0.46765372 | F38: =F31 -> 0.52098775 | G38: =G31/H31 -> 0.405 | H38: =SQRT(SUMSQ(D38:G38)) -> 0.80880256
B40: Magnitud | D40: u_Presión transmisor (Pt) (psi) | E40: Grados de libertad | F40: Coeficiente de sensibilidad
B41: Transmisor de presión VST1 - 1000 psi | D41: =H34 -> 0.62301275 | E41: =+(D41^4)/(((D34^4)/200)+((E34^4)/50)+((F34^4)/12)+((G34^4)/200)) -> 116.45027 | F41: 1
B42: Transmisor de presión VST1 - 5000 psi | D42: =H35 -> 1.4422442 | E42: =+(D42^4)/(((D35^4)/200)+((E35^4)/50)+((F35^4)/11)+((G35^4)/200)) -> 48.339495 | F42: 1
B43: Transmisor de presión VST2 - 145 psi | D43: =H36 -> 0.040447507 | E43: =+(D43^4)/(((D36^4)/200)+((E36^4)/50)+((F36^4)/9)+((G36^4)/200)) -> 128.40151 | F43: 1
B44: Transmisor de presión VST2 - 870 psi | D44: =H37 -> 0.078603851 | E44: =+(D44^4)/(((D37^4)/200)+((E37^4)/50)+((F37^4)/10)+((G37^4)/200)) -> 77.97951 | F44: 1
B45: Transmisor de presión VST2 - 3625 psi | D45: =H38 -> 0.80880256 | E45: =+(D45^4)/(((D38^4)/200)+((E38^4)/50)+((F38^4)/11)+((G38^4)/200)) -> 54.942173 | F45: 1
...

Sheet CONTROL DE CAMBIOS
C1: CERTIFICADO DE CALIBRACIÓN VÁLVULAS DE SEGURIDAD REPORTES VST
C3: CÓDIGO | D3: OHSQ-FO-44 | E3: VERSIÓN | F3: 08 | G3: FECHA | H3: 46008
A5: CONTROL DE CAMBIOS
A7: FECHA | B7: VERSIÓN | C7: DESCRIPCIÓN | G7: AUTOR
A8: 45364 | B8: 01 | C8: Creación del documento | G8: Andres Felipe Ovalle Ortiz Asesor Comercial
A9: 45454 | B9: 02 | C9: Modificiacion estructura y formulas | G9: Camilo Andres Fajardo Hoyos Asesor Comercial
A10: 45457 | B10: 03 | C10: Modificación estructura y formulas | G10: Julian Camilo Romero huertas Asesor Comercial
A11: 45803 | B11: 04 | C11: Se modifica totalmente el formato para poder cumplir con la norma, adicionalmente se añaden todas las contribuciones de incertidumbre | G11: Andres Felipe Ovalle Ortiz Asesor Comercial
A12: 45856 | B12: 05 | C12: Se añade la celda de 0,5T al formato, además de actualizar nuevamente la incertidumbre con las últimas calibraciones. | G12: Andres Felipe Ovalle Ortiz Asesor Comercial
A13: 45895 | B13: 06 | C13: Actualización del documento, se complementa el método utilizado, se complementa el lugar de prueba, ajuste de redacción de la especificación y se modifica la redacción de los participantes de la calibración | G13: Andres Felipe Ovalle Ortiz Asesor Comercial
A14: 45917 | B14: 07 | C14: Actualización del documento con cambios de forma e incluyendo los descargos de responsabilidad | G14: Andres Felipe Ovalle Ortiz Asesor Comercial
A15: 46008 | B15: 09 | C15: Se actualiza el logo, para cambiarlo junto con el simbolo de acreditado ONAC | G15: Andres Felipe Ovalle Ortiz Líder de laboratorio
A21: CONTROL DE REVISIONES
A22: ELABORADO POR | C22: REVISADO POR | E22: APROBADO POR
A24: Nombre: | B24: Andres Felipe Ovalle Ortiz | C24: Nombre: | D24: Camilo Andres Fajardo Hoyos | E24: Nombre: | F24: Carlos Alberto Suarez Franco
A25: Cargo: | B25: Líder de laboratorio | C25: Cargo: | D25: Director Comercial | E25: Cargo: | F25: Gerente General
A26: Fecha: | B26: 46008 | C26: Fecha: | D26: 46008 | E26: Fecha: | F26: 46008
